Workbook

Sheet TREINAMENTO DE NR 35
C1: LISTA DE PRESENÇA
C2: NR 35 - NR 35 - TRABALHO EM ALTURA
A3: EMPRESA | D3: OBRA | F3: DATA
A4: Aahbrant Engenharia e Construções LTDA | D4: BEIRA RIO | F4: 46260
A5: INSTRUTOR | D5: LOCAL DO TREINAMENTO | F5: CARGA HORÁRIA
A6: GILTON PEREIRA MIRANDA | D6: SALA DE TREINAMENTO | F6: 8 HORAS
A7: ASSUNTOS ABORDADOS DAS 08:00h às 16:00h
A8: Normas e regulamentos aplicáveis ao trabalho em altura; Análise de Risco e condições impeditivas; Riscos potenciais inerentes ao trabalho em altura e medidas de prevenção e controle; Sistemas, equipamentos e procedimentos de proteção coletiva; Equipamentos de Proteção Individual para trabalho em altura: seleção, inspeção, conservação e limitação de uso; Acidentes típicos em trabalhos em altura; Condutas em situações de emergência, incluindo noções de técnicas de resgate e de primeiros socorros. Atividade pratica e atividade especifica (sistema de ancoragem, linha de vida) Treinamento prático.'PRATICO: CINTO DE SEGURANÇA (SISTEMA DE ANCORAGEM E LINHA DE VIDA)
A29: PRATICO: CINTO DE SEGURANÇA (SISTEMA DE ANCORAGEM E LINHA DE VIDA) ANDAIMES E MONTAGEM DE ANDAIMES.
A32: Nº | B32: Mat: | C32: Nome do colaborador | E32: Função | F32: Assinatura
A33: 1 | B33: 550 | C33: =VLOOKUP(B33,'MATRIZ FUNCIONÁRIOS'!A:H,2,0) -> JOSÉ IGOR GALVÃO SILVA | E33: =VLOOKUP(B33,'MATRIZ FUNCIONÁRIOS'!A:H,3,0) -> AJUDANTE DE OBRAS
A34: 2 | C34: =VLOOKUP(B34,'MATRIZ FUNCIONÁRIOS'!A:H,2,0) -> #N/A | E34: =VLOOKUP(B34,'MATRIZ FUNCIONÁRIOS'!A:H,3,0) -> #N/A
A35: 3 | C35: =VLOOKUP(B35,'MATRIZ FUNCIONÁRIOS'!A:H,2,0) -> #N/A | E35: =VLOOKUP(B35,'MATRIZ FUNCIONÁRIOS'!A:H,3,0) -> #N/A
A36: 4 | C36: =VLOOKUP(B36,'MATRIZ FUNCIONÁRIOS'!A:H,2,0) -> #N/A | E36: =VLOOKUP(B36,'MATRIZ FUNCIONÁRIOS'!A:H,3,0) -> #N/A
A37: 5 | C37: =VLOOKUP(B37,'MATRIZ FUNCIONÁRIOS'!A:H,2,0) -> #N/A | E37: =VLOOKUP(B37,'MATRIZ FUNCIONÁRIOS'!A:H,3,0) -> #N/A
A38: 6 | C38: =VLOOKUP(B38,'MATRIZ FUNCIONÁRIOS'!A:H,2,0) -> #N/A | E38: =VLOOKUP(B38,'MATRIZ FUNCIONÁRIOS'!A:H,3,0) -> #N/A
A39: 7 | C39: =VLOOKUP(B39,'MATRIZ FUNCIONÁRIOS'!A:H,2,0) -> #N/A | E39: =VLOOKUP(B39,'MATRIZ FUNCIONÁRIOS'!A:H,3,0) -> #N/A
A40: 8 | C40: =VLOOKUP(B40,'MATRIZ FUNCIONÁRIOS'!A:H,2,0) -> #N/A | E40: =VLOOKUP(B40,'MATRIZ FUNCIONÁRIOS'!A:H,3,0) -> #N/A
A41: 9 | C41: =VLOOKUP(B41,'MATRIZ FUNCIONÁRIOS'!A:H,2,0) -> #N/A | E41: =VLOOKUP(B41,'MATRIZ FUNCIONÁRIOS'!A:H,3,0) -> #N/A
A42: 10 | C42: =VLOOKUP(B42,'MATRIZ FUNCIONÁRIOS'!A:H,2,0) -> #N/A | E42: =VLOOKUP(B42,'MATRIZ FUNCIONÁRIOS'!A:H,3,0) -> #N/A
A43: 11 | C43: =VLOOKUP(B43,'MATRIZ FUNCIONÁRIOS'!A:H,2,0) -> #N/A | E43: =VLOOKUP(B43,'MATRIZ FUNCIONÁRIOS'!A:H,3,0) -> #N/A
A44: ASSINATURA DO INSTRUTOR DO TREINAMENTO

Sheet CERTIFICADO DE NR 35
C7: CERTIFICADO
C12: Certificamos que o Sr. | G12: ='ORDEM DE SERVIÇO'!B9 -> JOSE ANDRE DE SANTANA CRISPIM | M12: portador do RG: | Q12: ='ORDEM DE SERVIÇO'!B40 -> 3140099
C13: participou do Curso de Formação Básico em Segurança em Trabalho em altura, em conformidade
C14: com a NR 35, no período de | H14: =F22 -> 46260 | K14: na função | M14: ='ORDEM DE SERVIÇO'!D9 -> AJUDANTE DE OBRAS
C15: ='TREINAMENTO DE NR 35'!A29 -> PRATICO: CINTO DE SEGURANÇA (SISTEMA DE ANCORAGEM E LINHA DE VIDA) ANDAIMES E MONTAGEM DE ANDAIMES.
C17: promovido pelo SESMT da Empresa Aahbrant Engenharia e Construções LTDA, CNPJ 23.837.456/0002-97
C18: AV PRESIDENTE EPITACIO PESSOA, 753,ANDAR 11 SALA 1108,ESTADOS, JOAO PESSOA-PB
C19: OBRA BEIRA RIO
C22: ESTADOS, JOAO PESSOA-PB | F22: ='TREINAMENTO DE NR 35'!F4 -> 46260
C26: GILTON PEREIRA MIRANDA | N26: ='ORDEM DE SERVIÇO'!B39 -> JOSE ANDRE DE SANTANA CRISPIM
C27: TEC SEGURANÇA DO TRABALHO | N27: ='ORDEM DE SERVIÇO'!B41 -> AJUDANTE DE OBRAS
C28: Registro MTE-0123056/SP
C29: INSTRUTOR
O30: ESTADOS, JOAO PESSOA-PB
C40: CONTEUDO PROGRAMÁTICO
C46: Normas e regulamentos aplicáveis ao trabalho em altura; Análise de Risco e condições impeditivas; Riscos potenciais inerentes ao trabalho em altura e medidas de prevenção e controle; Sistemas, equipamentos e procedimentos de proteção coletiva; Equipamentos de Proteção Individual para trabalho em altura: seleção, inspeção, conservação e limitação de uso; Acidentes típicos em trabalhos em altura; Condutas em situações de emergência, incluindo noções de técnicas de resgate e de primeiros socorros. Atividade pratica e atividade especifica (sistema de ancoragem, linha de vida) Treinamento prático.
C64: ='TREINAMENTO DE NR 35'!A29 -> PRATICO: CINTO DE SEGURANÇA (SISTEMA DE ANCORAGEM E LINHA DE VIDA) ANDAIMES E MONTAGEM DE ANDAIMES.
C68: GILTON PEREIRA MIRANDA | I68: ='ORDEM DE SERVIÇO'!B39 -> JOSE ANDRE DE SANTANA CRISPIM | N68: AV PRESIDENTE EPITACIO PESSOA, 753,ANDAR 11 SALA 1108
C69: TEC SEGURANÇA DO TRABALHO | I69: ='ORDEM DE SERVIÇO'!B41 -> AJUDANTE DE OBRAS | O69: ESTADOS, JOAO PESSOA-PB
C70: Registro MTE-SP 012305/6
C71: INSTRUTOR

Sheet TREINAMENTO DE NR 11
C1: LISTA DE PRESENÇA
C2: NR-11 TREINAMENTO ESPECIFICO OPERADOR DE MAQUINAS
A3: EMPRESA | F3: DATA
A4: Aahbrant Engenharia e Construções LTDA | D4: OBRA BEIRA RIO | F4: 45757
A5: INSTRUTOR | D5: LOCAL DO TREINAMENTO | F5: CARGA HORÁRIA
A6: GILTON PEREIRA MIRANDA | D6: SALA DE TREINAMENTO AAHBRANT | F6: 8 HORAS
A7: ASSUNTOS ABORDADOS DAS 08:00h às 16:00h
A8: Princípios básicos da operação de máquinas pesadas;
A9: Técnicas de operação de máquinas pesadas como escavação, movimentação de cargas, etc;
A10: Normas regulamentadoras (como as NRs 05, 06, 07, 09 e 11);
A11: Responsabilidades do operador de máquinas;
A12: Principais sistemas e componentes de máquinas e equipamentos;
A13: Inspeção inicial da máquina ou equipamento;
A14: A importância da manutenção corretiva e preventiva;
A15: Lista de verificação (checklist);
A16: Cuidados para a utilização da máquina;
A17: Práticas recomendáveis para o uso de máquinas e equipamentos;
A18: Cuidados com pneus e rodas;
... A24: Treinamento para as máquinas: CAMINHÃO MUNCK, ROLO COMPACTADOR, ROLO CHAPA E PNEU, BOBCAT, ROLO PATA DE CARNEIRO, FRESADORA DE ASFALTICO, ESCAVADEIRA HIDRÁULICA RETROESCAVADEIRA E MOTONIVELADORA (PATROL).
A26: Nº | B26: Mat: | C26: Nome do colaborador | E26: Função | F26: Assinatura
A27: 1 | B27: ='ORDEM DE SERVIÇO'!D7 -> 25 | C27: =VLOOKUP(B27,'MATRIZ FUNCIONÁRIOS'!A:H,2,0) -> JOSE ANDRE DE SANTANA CRISPIM | E27: =VLOOKUP(B27,'MATRIZ FUNCIONÁRIOS'!A:H,3,0) -> AJUDANTE DE OBRAS | F27: X
A28: 2 | C28: =VLOOKUP(B28,'MATRIZ FUNCIONÁRIOS'!A:H,2,0) -> #N/A | E28: =VLOOKUP(B28,'MATRIZ FUNCIONÁRIOS'!A:H,3,0) -> #N/A
A29: 3 | C29: =VLOOKUP(B29,'MATRIZ FUNCIONÁRIOS'!A:H,2,0) -> #N/A | E29: =VLOOKUP(B29,'MATRIZ FUNCIONÁRIOS'!A:H,3,0) -> #N/A
A30: 4 | C30: =VLOOKUP(B30,'MATRIZ FUNCIONÁRIOS'!A:H,2,0) -> #N/A | E30: =VLOOKUP(B30,'MATRIZ FUNCIONÁRIOS'!A:H,3,0) -> #N/A
A31: 5 | C31: =VLOOKUP(B31,'MATRIZ FUNCIONÁRIOS'!A:H,2,0) -> #N/A | E31: =VLOOKUP(B31,'MATRIZ FUNCIONÁRIOS'!A:H,3,0) -> #N/A
A32: 6 | C32: =VLOOKUP(B32,'MATRIZ FUNCIONÁRIOS'!A:H,2,0) -> #N/A | E32: =VLOOKUP(B32,'MATRIZ FUNCIONÁRIOS'!A:H,3,0) -> #N/A
A33: 7 | C33: =VLOOKUP(B33,'MATRIZ FUNCIONÁRIOS'!A:H,2,0) -> #N/A | E33: =VLOOKUP(B33,'MATRIZ FUNCIONÁRIOS'!A:H,3,0) -> #N/A
A34: 8 | C34: =VLOOKUP(B34,'MATRIZ FUNCIONÁRIOS'!A:H,2,0) -> #N/A | E34: =VLOOKUP(B34,'MATRIZ FUNCIONÁRIOS'!A:H,3,0) -> #N/A
A35: 9 | C35: =VLOOKUP(B35,'MATRIZ FUNCIONÁRIOS'!A:H,2,0) -> #N/A | E35: =VLOOKUP(B35,'MATRIZ FUNCIONÁRIOS'!A:H,3,0) -> #N/A
A36: 10 | C36: =VLOOKUP(B36,'MATRIZ FUNCIONÁRIOS'!A:H,2,0) -> #N/A | E36: =VLOOKUP(B36,'MATRIZ FUNCIONÁRIOS'!A:H,3,0) -> #N/A
A37: 11 | C37: =VLOOKUP(B37,'MATRIZ FUNCIONÁRIOS'!A:H,2,0) -> #N/A | E37: =VLOOKUP(B37,'MATRIZ FUNCIONÁRIOS'!A:H,3,0) -> #N/A
A38: ASSINATURA DO INSTRUTOR DO TREINAMENTO

Sheet CERTIFICADO DE NR 11
C7: CERTIFICADO
C12: Certificamos que o Sr. | G12: ='ORDEM DE SERVIÇO'!B9 -> JOSE ANDRE DE SANTANA CRISPIM | M12: portador do RG: | Q12: ='ORDEM DE SERVIÇO'!B40 -> 3140099
C13: participou do Curso de Segurança em Trabalho em Maquinas e Equipamentos, em conformidade
C14: com a NR 12, no período de | H14: =F23 -> 45757 | K14: na função | M14: ='ORDEM DE SERVIÇO'!D9 -> AJUDANTE DE OBRAS
C15: ='TREINAMENTO DE NR 11'!A24 -> Treinamento para as máquinas: CAMINHÃO MUNCK, ROLO COMPACTADOR, ROLO CHAPA E PNEU, BOBCAT, ROLO PATA DE CARNEIRO, FRESADORA DE ASFALTICO, ESCAVADEIRA HIDRÁULICA RETROESCAVADEIRA E MOTONIVELADORA (PATROL).
C18: promovido pelo SESMT da EmpresaAahbrant Engenharia e Construções LTDA, CNPJ 23.837.456/0002-97 ,
C19: sede da empresa AV PRESIDENTE EPITACIO PESSOA, 753,ANDAR 11 SALA 1108,ESTADOS, JOAO PESSOA-PB
C21: com carga horária de 08 h.
C23: Barueri, SP, data: | F23: ='TREINAMENTO DE NR 11'!F4 -> 45757
N26: x
C27: GILTON PEREIRA MIRANDA | I27: GILTON PEREIRA MIRANDA | N27: ='ORDEM DE SERVIÇO'!B39 -> JOSE ANDRE DE SANTANA CRISPIM
C28: TEC SEGURANÇA DO TRABALHO | I28: TÉC SEGURANÇA DO TRABALHO | N28: ='ORDEM DE SERVIÇO'!B41 -> AJUDANTE DE OBRAS
C29: Registro MTE-0123056/SP | I29: MTE-0123056/SP
I30: RESP TÉCNICO | N30: AV PRESIDENTE EPITACIO PESSOA, 753,ANDAR 11 SALA 1108
O31: ESTADOS, JOAO PESSOA-PB
C40: CONTEUDO PROGRAMÁTICO
C46: A capacitação para operação segura de máquinas.
C47: a) descrição e identificação dos riscos associados com cada máquina e equipamento e as proteções específicas contra cada um deles;
C48: b) funcionamento das proteções; como e por que devem ser usadas;
C49: c) como e em que circunstâncias uma proteção pode ser removida, e por quem, sendo na maioria dos casos, somente o pessoal de inspeção ou manutenção;
C50: d) o que fazer, por exemplo, contatar o supervisor, se uma proteção foi danificada ou se perdeu sua função, deixando
C51: de garantir uma segurança adequada;
C52: e) os princípios de segurança na utilização da máquina ou equipamento;
C53: f) segurança para riscos mecânicos, elétricos e outros relevantes;
C54: g) método de trabalho seguro;
C55: h) permissão de trabalho; e
C56: i) sistema de bloqueio de funcionamento da máquina e equipamento durante operações de inspeção, limpeza, lubrificação e manutenção.
... C65: h) noções sobre prestação de primeiros socorros.
C66: ='TREINAMENTO DE NR 11'!A24 -> Treinamento para as máquinas: CAMINHÃO MUNCK, ROLO COMPACTADOR, ROLO CHAPA E PNEU, BOBCAT, ROLO PATA DE CARNEIRO, FRESADORA DE ASFALTICO, ESCAVADEIRA HIDRÁULICA RETROESCAVADEIRA E MOTONIVELADORA (PATROL).
C68: GILTON PEREIRA MIRANDA | I68: ='ORDEM DE SERVIÇO'!B39 -> JOSE ANDRE DE SANTANA CRISPIM
C69: TÉC SEGURANÇA DO TRABALHO | I69: ='ORDEM DE SERVIÇO'!B41 -> AJUDANTE DE OBRAS
C70: MTE-0123056/SP
C71: RESP TÉCNICO

Sheet TREINAMENTO DE NR 12 PORTATEIS
C1: LISTA DE PRESENÇA
C2: NR 12 - SEGURANÇA NO TRABALHO EM MÁQUINAS E EQUIPAMENTOS
A3: EMPRESA | D3: LOCAL DO TREINAMENTO | F3: DATA
A4: Aahbrant Engenharia e Construções LTDA | D4: SALA DE TREINAMENTO-SEDE AAHBRANT | F4: 46252
A5: INSTRUTOR | D5: LOCAL DO TREINAMENTO | F5: CARGA HORÁRIA
A6: GILTON PEREIRA MIRANDA | D6: SALA DE TREINAMENTO | F6: 6 HORAS
A7: ASSUNTOS ABORDADOS DAS 08:00h às 16:00h
A8: Capacitação para operação segura de máquinas. a) descrição e identificação dos riscos associados com cada máquina e equipamento e as proteções específicas contra cada um deles; b) funcionamento das proteções; como e por que devem ser usadas; c) como e em que circunstâncias uma proteção pode ser removida, e por quem, sendo na maioria dos casos, somente o pessoal de inspeção ou manutenção; d) o que fazer, por exemplo, contatar o supervisor,se uma proteção foi danificada ou se perdeu sua função,deixando de garantir uma segurança adequada; e) os princípios de segurança na utilização da máquina ou equipamento; f) segurança para riscos mecânicos, elétricos e outros relevantes; g) método de trabalho seguro; h) permissão de trabalho; e i) sistema de bloqueio de funcionamento da máquina e equipamento durante operações de inspeção, limpeza, lubrificação e manutenção. Etapas teórica e prática a) noções sobre legislação de trânsito e de legislação de segurança e saúde no trabalho; b) noções sobre acidentes e doenças decorrentes da exposição aos riscos existentes na máquina, equipamentos e implementos; c) medidas de controle dos riscos: EPC e EPI; d) operação com segurança da máquina ou equipamento; e) inspeção, regulagem e manutenção com segurança; f) sinalização de segurança; g) procedimentos em situação de emergência; e h) noções sobre prestação de primeiros socorros. Maquinas utilizadas nas aulas praticas:
A30: SERRA CIRCULAR, MAKITA, FERRAMENTAS ELÉTRICAS E DIVERSAS
A34: Nº | B34: Mat: | C34: Nome do colaborador | E34: Função | F34: Assinatura
A35: 1 | B35: 548 | C35: =VLOOKUP(B35,'MATRIZ FUNCIONÁRIOS'!A:H,2,0) -> LUCIANO DA SILVA | E35: =VLOOKUP(B35,'MATRIZ FUNCIONÁRIOS'!A:H,3,0) -> AJUDANTE DE OBRAS
A36: 2 | C36: =VLOOKUP(B36,'MATRIZ FUNCIONÁRIOS'!A:H,2,0) -> #N/A | E36: =VLOOKUP(B36,'MATRIZ FUNCIONÁRIOS'!A:H,3,0) -> #N/A
A37: 3 | C37: =VLOOKUP(B37,'MATRIZ FUNCIONÁRIOS'!A:H,2,0) -> #N/A | E37: =VLOOKUP(B37,'MATRIZ FUNCIONÁRIOS'!A:H,3,0) -> #N/A
A38: 4 | C38: =VLOOKUP(B38,'MATRIZ FUNCIONÁRIOS'!A:H,2,0) -> #N/A | E38: =VLOOKUP(B38,'MATRIZ FUNCIONÁRIOS'!A:H,3,0) -> #N/A
A39: 5 | C39: =VLOOKUP(B39,'MATRIZ FUNCIONÁRIOS'!A:H,2,0) -> #N/A | E39: =VLOOKUP(B39,'MATRIZ FUNCIONÁRIOS'!A:H,3,0) -> #N/A
A40: 6 | C40: =VLOOKUP(B40,'MATRIZ FUNCIONÁRIOS'!A:H,2,0) -> #N/A | E40: =VLOOKUP(B40,'MATRIZ FUNCIONÁRIOS'!A:H,3,0) -> #N/A
A41: 7 | C41: =VLOOKUP(B41,'MATRIZ FUNCIONÁRIOS'!A:H,2,0) -> #N/A | E41: =VLOOKUP(B41,'MATRIZ FUNCIONÁRIOS'!A:H,3,0) -> #N/A
A42: 8 | C42: =VLOOKUP(B42,'MATRIZ FUNCIONÁRIOS'!A:H,2,0) -> #N/A | E42: =VLOOKUP(B42,'MATRIZ FUNCIONÁRIOS'!A:H,3,0) -> #N/A
A43: 9 | C43: =VLOOKUP(B43,'MATRIZ FUNCIONÁRIOS'!A:H,2,0) -> #N/A | E43: =VLOOKUP(B43,'MATRIZ FUNCIONÁRIOS'!A:H,3,0) -> #N/A
A44: 10 | C44: =VLOOKUP(B44,'MATRIZ FUNCIONÁRIOS'!A:H,2,0) -> #N/A | E44: =VLOOKUP(B44,'MATRIZ FUNCIONÁRIOS'!A:H,3,0) -> #N/A
A45: 11 | C45: =VLOOKUP(B45,'MATRIZ FUNCIONÁRIOS'!A:H,2,0) -> #N/A | E45: =VLOOKUP(B45,'MATRIZ FUNCIONÁRIOS'!A:H,3,0) -> #N/A
A46: ASSINATURA DO INSTRUTOR DO TREINAMENTO

Sheet CERTIFICADO DE NR 12 PORTATEIS
C7: CERTIFICADO
C12: Certificamos que o Sr. | G12: ='ORDEM DE SERVIÇO'!B9 -> JOSE ANDRE DE SANTANA CRISPIM | M12: portador do RG: | Q12: ='ORDEM DE SERVIÇO'!B40 -> 3140099
C13: participou do Curso de Segurança em Trabalho em Maquinas e Equipamentos, em conformidade
C14: com a NR 12, no período de | H14: =F21 -> 46252 | K14: na função de | M14: ='ORDEM DE SERVIÇO'!D9 -> AJUDANTE DE OBRAS
C15: para Maquinas | F15: SERRA CIRCULAR, MAKITA, FERRAMENTAS ELÉTRICAS E DIVERSAS
C16: promovido pelo SESMT da Empresa , Aahbrant Engenharia e Construções LTDA, CNPJ 23.837.456/0002-9
C17: sede da empresa na AV PRESIDENTE EPITACIO PESSOA, 753,ANDAR 11 SALA 1108,ESTADOS, JOAO PESSOA-PB.
C18: , com carga horária de 06 horas.
C21: JOÁO PESSOA, PB | F21: 46252
C26: GILTON PEREIRA MIRANDA | N26: ='ORDEM DE SERVIÇO'!B39 -> JOSE ANDRE DE SANTANA CRISPIM
C27: TEC SEGURANÇA DO TRABALHO | N27: ='ORDEM DE SERVIÇO'!B41 -> AJUDANTE DE OBRAS
C28: Registro MTE-0123056/SP | N28: Registro MTE-SP 012305/6
C40: CONTEUDO PROGRAMÁTICO
C46: A capacitação para operação segura de máquinas.
C47: a) descrição e identificação dos riscos associados com cada máquina e equipamento e as proteções específicas contra cada um deles;
C48: b) funcionamento das proteções; como e por que devem ser usadas;
C49: c) como e em que circunstâncias uma proteção pode ser removida, e por quem, sendo na maioria dos casos, somente o pessoal de inspeção ou manutenção;
C50: d) o que fazer, por exemplo, contatar o supervisor, se uma proteção foi danificada ou se perdeu sua função, deixando de garantir uma segurança adequada;
C51: e) os princípios de segurança na utilização da máquina ou equipamento;
C52: f) segurança para riscos mecânicos, elétricos e outros relevantes;
C53: g) método de trabalho seguro;
C54: h) permissão de trabalho; e
C55: i) sistema de bloqueio de funcionamento da máquina e equipamento durante operações de inspeção, limpeza, lubrificação e manutenção.
C57: Etapas teórica e prática
... C65: h) noções sobre prestação de primeiros socorros.
C66: Maquina utilizados nas aulas praticas: | H66: =F15 -> SERRA CIRCULAR, MAKITA, FERRAMENTAS ELÉTRICAS E DIVERSAS

Sheet TREINAMENTO DE NR 12
C1: LISTA DE PRESENÇA
C2: NR 12 - SEGURANÇA NO TRABALHO EM MÁQUINAS E EQUIPAMENTOS
A3: EMPRESA | F3: DATA
A4: Aahbrant Engenharia e Construções LTDA | F4: 45769
A5: INSTRUTOR | D5: LOCAL DO TREINAMENTO | F5: CARGA HORÁRIA
A6: GILTON PEREIRA MIRANDA | D6: SALA DE TREINAMENTO AAHBRANT | F6: 08 HORAS
A7: ASSUNTOS ABORDADOS DAS 08:00h às 16:00h
A8: Capacitação para operação segura de máquinas. a) descrição e identificação dos riscos associados com cada máquina e equipamento e as proteções específicas contra cada um deles; b) funcionamento das proteções; como e por que devem ser usadas; c) como e em que circunstâncias uma proteção pode ser removida, e por quem, sendo na maioria dos casos, somente o pessoal de inspeção ou manutenção; d) o que fazer, por exemplo, contatar o supervisor,se uma proteção foi danificada ou se perdeu sua função,deixando de garantir uma segurança adequada; e) os princípios de segurança na utilização da máquina ou equipamento; f) segurança para riscos mecânicos, elétricos e outros relevantes; g) método de trabalho seguro; h) permissão de trabalho; e i) sistema de bloqueio de funcionamento da máquina e equipamento durante operações de inspeção, limpeza, lubrificação e manutenção. Etapas teórica e prática a) noções sobre legislação de trânsito e de legislação de segurança e saúde no trabalho; b) noções sobre acidentes e doenças decorrentes da exposição aos riscos existentes na máquina, equipamentos e implementos; c) medidas de controle dos riscos: EPC e EPI; d) operação com segurança da máquina ou equipamento; e) inspeção, regulagem e manutenção com segurança; f) sinalização de segurança; g) procedimentos em situação de emergência; e h) noções sobre prestação de primeiros socorros.
A29: Treinamento para as máquinas: ROLO COMPACTADOR, ROLO CHAPA E PNEU, BOBCAT, ROLO PATA DE CARNEIRO, FRESADORA DE ASFALTICO, ESCAVADEIRA HIDRÁULICA RETROESCAVADEIRA E MOTONIVELADORA (PATROL).
A32: Nº | B32: Mat: | C32: Nome do colaborador | E32: Função | F32: Assinatura
A33: 1 | B33: ='ORDEM DE SERVIÇO'!D7 -> 25 | C33: =VLOOKUP(B33,'MATRIZ FUNCIONÁRIOS'!A:H,2,0) -> JOSE ANDRE DE SANTANA CRISPIM | E33: =VLOOKUP(B33,'MATRIZ FUNCIONÁRIOS'!A:H,3,0) -> AJUDANTE DE OBRAS | F33: X
A34: 2 | C34: =VLOOKUP(B34,'MATRIZ FUNCIONÁRIOS'!A:H,2,0) -> #N/A | E34: =VLOOKUP(B34,'MATRIZ FUNCIONÁRIOS'!A:H,3,0) -> #N/A
A35: 3 | C35: =VLOOKUP(B35,'MATRIZ FUNCIONÁRIOS'!A:H,2,0) -> #N/A | E35: =VLOOKUP(B35,'MATRIZ FUNCIONÁRIOS'!A:H,3,0) -> #N/A
A36: 4 | C36: =VLOOKUP(B36,'MATRIZ FUNCIONÁRIOS'!A:H,2,0) -> #N/A | E36: =VLOOKUP(B36,'MATRIZ FUNCIONÁRIOS'!A:H,3,0) -> #N/A
A37: 5 | C37: =VLOOKUP(B37,'MATRIZ FUNCIONÁRIOS'!A:H,2,0) -> #N/A | E37: =VLOOKUP(B37,'MATRIZ FUNCIONÁRIOS'!A:H,3,0) -> #N/A
A38: 6 | C38: =VLOOKUP(B38,'MATRIZ FUNCIONÁRIOS'!A:H,2,0) -> #N/A | E38: =VLOOKUP(B38,'MATRIZ FUNCIONÁRIOS'!A:H,3,0) -> #N/A
A39: 7 | C39: =VLOOKUP(B39,'MATRIZ FUNCIONÁRIOS'!A:H,2,0) -> #N/A | E39: =VLOOKUP(B39,'MATRIZ FUNCIONÁRIOS'!A:H,3,0) -> #N/A
A40: 8 | C40: =VLOOKUP(B40,'MATRIZ FUNCIONÁRIOS'!A:H,2,0) -> #N/A | E40: =VLOOKUP(B40,'MATRIZ FUNCIONÁRIOS'!A:H,3,0) -> #N/A
A41: 9 | C41: =VLOOKUP(B41,'MATRIZ FUNCIONÁRIOS'!A:H,2,0) -> #N/A | E41: =VLOOKUP(B41,'MATRIZ FUNCIONÁRIOS'!A:H,3,0) -> #N/A
A42: 10 | C42: =VLOOKUP(B42,'MATRIZ FUNCIONÁRIOS'!A:H,2,0) -> #N/A | E42: =VLOOKUP(B42,'MATRIZ FUNCIONÁRIOS'!A:H,3,0) -> #N/A
A43: 11 | C43: =VLOOKUP(B43,'MATRIZ FUNCIONÁRIOS'!A:H,2,0) -> #N/A | E43: =VLOOKUP(B43,'MATRIZ FUNCIONÁRIOS'!A:H,3,0) -> #N/A
A44: ASSINATURA INSTRUTOR DO TREINAMENTO

Sheet CERTIFICADO DE NR 12
C7: CERTIFICADO
C12: Certificamos que o Sr. | G12: ='ORDEM DE SERVIÇO'!B9 -> JOSE ANDRE DE SANTANA CRISPIM | M12: portador do RG: | Q12: ='ORDEM DE SERVIÇO'!B40 -> 3140099
C13: participou do Curso de Segurança em Trabalho em Maquinas e Equipamentos, em conformidade
C14: com a NR 12, no período de | H14: =F23 -> 45758 | K14: na função | M14: ='ORDEM DE SERVIÇO'!D9 -> AJUDANTE DE OBRAS
C15: ='TREINAMENTO DE NR 12'!A29 -> Treinamento para as máquinas: ROLO COMPACTADOR, ROLO CHAPA E PNEU, BOBCAT, ROLO PATA DE CARNEIRO, FRESADORA DE ASFALTICO, ESCAVADEIRA HIDRÁULICA RETROESCAVADEIRA E MOTONIVELADORA (PATROL).
C18: promovido pelo SESMT da Empresa Aahbrant Engenharia e Construções LTDA, CNPJ 23.837.456/0002-97
C19: sede da empresa na sede da empresa AV PRESIDENTE EPITACIO PESSOA, 753,ANDAR 11 SALA 1108,ESTADOS, JOAO PESSOA-PB
C21: com carga horária de 08 h.
C23: JOÃO PESOA-PB | F23: 45758
N26: X
C27: GILTON PEREIRA MIRANDA | N27: ='ORDEM DE SERVIÇO'!B39 -> JOSE ANDRE DE SANTANA CRISPIM
C28: TEC SEGURANÇA DO TRABALHO | N28: ='ORDEM DE SERVIÇO'!B41 -> AJUDANTE DE OBRAS
C29: REGISTRO - MTE-0123056/SP
C40: CONTEUDO PROGRAMÁTICO
C46: A capacitação para operação segura de máquinas.
C47: a) descrição e identificação dos riscos associados com cada máquina e equipamento e as proteções específicas contra cada um deles;
C48: b) funcionamento das proteções; como e por que devem ser usadas;
C49: c) como e em que circunstâncias uma proteção pode ser removida, e por quem, sendo na maioria dos casos, somente o pessoal de inspeção ou manutenção;
C50: d) o que fazer, por exemplo, contatar o supervisor, se uma proteção foi danificada ou se perdeu sua função, deixando
C51: de garantir uma segurança adequada;
C52: e) os princípios de segurança na utilização da máquina ou equipamento;
C53: f) segurança para riscos mecânicos, elétricos e outros relevantes;
C54: g) método de trabalho seguro;
C55: h) permissão de trabalho; e
... C65: h) noções sobre prestação de primeiros socorros.
C66: ='TREINAMENTO DE NR 12'!A29 -> Treinamento para as máquinas: ROLO COMPACTADOR, ROLO CHAPA E PNEU, BOBCAT, ROLO PATA DE CARNEIRO, FRESADORA DE ASFALTICO, ESCAVADEIRA HIDRÁULICA RETROESCAVADEIRA E MOTONIVELADORA (PATROL).
C68: GILTON PEREIRA MIRANDA | I68: ='ORDEM DE SERVIÇO'!B39 -> JOSE ANDRE DE SANTANA CRISPIM
C69: TEC SEGURANÇA DO TRABALHO | I69: ='ORDEM DE SERVIÇO'!B41 -> AJUDANTE DE OBRAS
C70: MTE-SP 0123056
D71: RESP TÉCNICO

Sheet TREINAMENTO DE INTEGRAÇÃO
C1: FORMULÁRIO | F1: FO.M. VER. 00 fl. 01/01
C2: TREINAMENTO DE INTEGRAÇÃO
A3: Nome da Empresa: | F3: Data:
A4: Aahbrant Engenharia e Construções LTDA | F4: 46259
A5: Responsável pelo treinamento: | F5: Assinatura do Responsável:
A6: GILTON PEREIRA MIRANDA
A7: Declaro ter participado do Treinamento de Integração NA SEDE DA EMPRESA TALUDE CONSTRUÇÕES S.A , dentro do horário normal de trabalho, com carga horária de quatro (04) horas conforme 18.14 Anexo-l, recebendo orientações e informações necessárias para que eu possa iniciar meu trabalho, conforme descrito abaixo: • Informações sobre as condições e meio ambiente de trabalho; • PGR - Plano de Gerenciamento de Resíduos; • Contenção de Vazamento; • Perigos e Riscos, Aspectos e Impactos Ambientais; • Uso adequado dos Equipamentos de Proteção Individual; • Informações sobre os Equipamentos de Proteção Coletiva (EPC) existentes no canteiro de obras; • APR - Análise Preliminar de Riscos, PTR- Permissão de Trabalho de Riscos; • Trabalho em Altura; Instalações Elétricas; • Investigação e Análise de Incidentes, Comunicação de Incidentes; • Plano de Atendimento a Emergência (PAE); • PGR, PCMAT e PCMSO; • Noções básicas sobre SGQ na obra; • Monitoramento de recebimento, inspeção e armazenamento de materiais; • Política de Segurança do Trabalho Talude (Política do Sistema de Gestão Integrado CCR AutoBan); • Inspeção em Maquinas e equipamentos; • Isolamento e sinalização de segurança vias e marginais; • Proteção contra quedas; • Organização e limpeza do canteiro, preservação de equipamentos e ferramentas e terminalidade dos serviços; • Recomendações e Ações de Prevenção Covid 19 conforme legislação vigente. , AlcoolXDrogas . Manual de Normas e Condutas para Motorista no Trânsito; ECONOMIA DE ENERGIA; COLETA SELETIVA E RECICLAGEM. Declaro ainda que recebi cópias de procedimentos das operações a serem realizadas, conforme a NR-18.28.4. Estou ciente dos riscos inerentes ao trabalho que vou executar e sei que é necessário trabalhar com segurança, cumprindo e obedecendo as regras, regulamentos, procedimentos e padrões da minha empresa. Estou ciente que, se eu não cumpri-los, posso ser penalizado inclusive com a minha demissão.
A34: Nº | B34: Mat: | C34: Nome do colaborador | E34: Função | F34: Assinatura
A35: 1 | B35: ='ORDEM DE SERVIÇO'!D7 -> 25 | C35: =VLOOKUP(B35,'MATRIZ FUNCIONÁRIOS'!A:H,2,0) -> JOSE ANDRE DE SANTANA CRISPIM | E35: =VLOOKUP(B35,'MATRIZ FUNCIONÁRIOS'!A:H,3,0) -> AJUDANTE DE OBRAS | F35: X

Sheet CERTIFICADO DE NR 18
C7: CERTIFICADO
C12: Certificamos que o Sr.(a) | G12: ='ORDEM DE SERVIÇO'!B9 -> JOSE ANDRE DE SANTANA CRISPIM | M12: portador do RG: | Q12: ='ORDEM DE SERVIÇO'!B40 -> 3140099
C13: participou do Treinamento Admissional para novos funcionários, conforme NR-18, item 18.14 Anexo-l
C14: aprovada pela Portaria 3.214/78 do Ministério do Trabalho, realizada no dia | Q14: 46259
C15: promovido pelo SESMT da Empresa, Aahbrant Engenharia e Construções LTDA, CNPJ 23.837.456/0002-97
C16: sede da empresa na Estrada Ibateguara, 170 Jardim Mutinga, Tamboré, Barueri, SP
C17: realizado na – sede da empresa AV PRESIDENTE EPITACIO PESSOA, 753,ANDAR 11 SALA 1108,ESTADOS, JOAO PESSOA-PB
C18: com carga horária de 4 horas
C19: JOÁO PESSOA, PB, data: | F19: =Q14 -> 46259
C25: GILTON PEREIRA MIRANDA | N25: ='ORDEM DE SERVIÇO'!B39 -> JOSE ANDRE DE SANTANA CRISPIM
C26: TEC SEGURANÇA DO TRABALHO | N26: ='ORDEM DE SERVIÇO'!B41 -> AJUDANTE DE OBRAS
C27: Registro MTE-0123056/SP
C40: CERTIFICADO
C46: Informações sobre as condições e meio ambiente de trabalho;PGR - Plano de Gerenciamento de Resíduos; Contenção de Vazamento; Perigos e Riscos, Aspectos e Impactos Ambientais; Uso adequado dos Equipamentos de Proteção Individual;
C51: Informações sobre os Equipamentos de Proteção Coletiva (EPC) existentes no canteiro de obras; APR - Análise Preliminar da riscos, PTR- Permissão de Trabalho de Riscos;
C54: Trabalho em Altura; Instalações Elétricas; Investigação e Análise de Incidentes, Comunicação de Incidentes; Plano de Atendimento a Emergência (PAE);PGR e PCMSO; Noções básicas sobre SGQ na obra; Monitoramento de recebimento, inspeção e armazenamento de materiais; Política de Segurança do Trabalho Talude; Inspeção em Maquinas e equipamentos; Isolamento e sinalização de segurança vias e marginais;
C59: Proteção contra quedas; Organização e limpeza do canteiro, preservação de equipamentos e ferramentas; Recomendações e Ações de Prevenção Covid 19 conforme legislação vigente; Álcool X Drogas; Manual de Normas e Condutas para Motorista no Trânsito.
I64: GILTON PEREIRA MIRANDA | N64: ='ORDEM DE SERVIÇO'!B9 -> JOSE ANDRE DE SANTANA CRISPIM
I65: TEC SEGURANÇA DO TRABALHO | N65: ='ORDEM DE SERVIÇO'!D9 -> AJUDANTE DE OBRAS
I66: Registro MTE-SP 0123056
I67: INSTRUTOR

Sheet ORDEM DE SERVIÇO
A1: AAHBRANT ENGENHARIA E CONSTRUÇÕES LTDA
A2: INSTRUÇÃO DE SEGURANÇA DO TRABALHO
A3: ORDEM DE SERVIÇO SOBRE HIGIENE, SEGURANÇA E MEDICINA DO TRABALHO
A4: Conforme estabelecido no item 1.7, letra “b”, NR-01 da Portaria 3214/MTE, cabe ao empregador elaborar Ordem de Serviço (OS) sobre Segurança e Medicina do Trabalho, dando ciência aos empregados.
A5: ORDEM DE SERVIÇO
A6: EMPRESA: | B6: AAHBRANT ENGENHARIA E CONSTRUÇÕES LTDA | C6: SETOR: | D6: =VLOOKUP(D8,'MATRIZ FUNCIONÁRIOS'!A:H,8) -> OPERACIONAL
A7: ELABORADO POR: | B7: GILTON PEREIRA MIRANDA | C7: MATRIC: | D7: 25
A8: CARGO: | B8: TEC. SEGURANÇA DO TRABALHO | C8: CBO: | D8: =VLOOKUP(D7,'MATRIZ FUNCIONÁRIOS'!A:D,4,FALSE) -> 717020
A9: FUNCIONÁRIO: | B9: =VLOOKUP(D7,'MATRIZ FUNCIONÁRIOS'!A:F,2,0) -> JOSE ANDRE DE SANTANA CRISPIM | C9: FUNÇÃO: | D9: =VLOOKUP(D7,'MATRIZ FUNCIONÁRIOS'!A:H,3,0) -> AJUDANTE DE OBRAS
A10: OBRIGAÇÕES DO EMPREGADO
A11: Considerando o interesse da empresa na redução de Acidentes do Trabalho, bem como cumprir o estabelecido no Artigo 157 – item II da C.L.T., com nova redação dada pela Lei n.º 6.514 de 22/12/77, fica determinado que é obrigação de todo empregado o cumprimento desta ordem de serviço e instrução de segurança do trabalho.
A12: DESCRIÇÃO DAS ATIVIDADES
A13: =VLOOKUP(D8,'MATRIZ FUNÇÃO'!A:E,3,0) -> Ajudam a executar tarefa de demolição de estrutura de alvenaria, Quebra de pisos e bases de concreto, construção e reparos em edificações de alvenaria, executar escavações, escoramento de valas e recomposição de pisos, Ajuda a executar paredes de alvenaria, executar trabalhos de retiradas de entulhos, espalhamento de materiais, carregamento e descarregamentos, desvios de trânsito auxilia na sinalização.
A14: RISCOS OCUPACIONAIS
A15: =VLOOKUP(D8,'MATRIZ FUNÇÃO'!A:E,4,0) -> FISICO: RUIDO, RADIAÇÃO NÃO IONIZANTES. QUÍMICO: POEIRAS MINERAIS (SILICA LIVRE CRISTALIZADA) ERGONOMICO: POSTURA INADEQUADA. ACIDENTE:ATROPELAMENTOS, BATIDAS CONTRA, CORTES E PERFURAÇÕES, PROJEÇÃO DE PARTICULAS, QUEDA DE MESMO NÍVEL.
A16: MEDIDAS PREVENTIVAS PARA REALIZAÇÃO DAS ATIVIDADES
A17: Ao utilizar escadas moveis procure fixa-la corretamente procurando apoiar-se pelo corrimão. Ao descer e subir escadas utilize o corrimão. Ao movimentar cargas e materiais procure mantê-la próximo do peito para proporcionar equilíbrio ao corpo. Ao alavancar cargas e materiais do piso manter a coluna ereta e usar as pernas como alavanca. Proibido realizar atividades para as quais não esteja capacitado, habilitado e autorizado pela empresa. Mesmo nas atividades em circuitos desnergizados utilizar luvas de borracha compatível com a voltagem do loca. Isole as partes vivas expostas dos circuitos provisórios. Atenção e cuidado com as partes moveis de maquinários, não manter contato direto com o equipamento em movimento. Fume somente nos locais permitidos que estejam sinalizados. Preservar o meio ambiente, não jogando lixos em locais inadequados. Use os EPI´s apenas para aas finalidades a que se destinam, guarde e conserve-os. Use protetor auditivo, quando trabalhar em local ruidoso. Use ferramentas manuais adequadas e as mantenha em boas condições para emprego. Somente ligue maquinas e equipamentos, com intermédio de conjunto de plug tomada. Evite emendas paralelas nos cabos/fios, use fita isolante adequada. Comparecer ao departamento medico para exame periódicos sempre que solicitado. Não improvise ferramentas, procure uma que seja adequada para seu serviço. Comunique ao seu encarregado toda e qualquer anormalidade ou defeito que notar na maquina ou ferramenta que for utilizar. Quando não souber ou tiver sobre algum serviço, pergunte ao encarregado, para prevenir-se contra possíveis acedentes. Não transite pela obra sem uniforme, capacete, óculos de segurança, protetor auditivo e botina de segurança. Nos trabalhos em altura superior a 2,00 (dois) metros na periferia do elevado, andaimes, estruturas, equipamentos, etc.. use o cinto De segurança. Não improvise andaimes de madeira, caixa e massa e nem trabalhe em andaimes sem guarda corpo, rodapé e estrado com mínimo De 0,60 cm de largura, chame seu encarregado. Obedecer as instruções do Técnico de Segurança, quando determinadas para você.
A18: TREINAMENTOS OBRIGATÓRIOS
A19: NR 05 CIPA
A20: NR 06 Equipamento de proteção individual;
A21: NR 17 Todos os empregados devem receber treinamentos ou instruções satisfatórias quanto aos métodos de trabalho, visando a garantir a execução de suas atividades com conforto e segurança;
A22: NR 23 Treinamento sobre princípios de incêndio e de como combatê-los;
A23: PROVIDÊNCIAS MÍNIMAS A SEREM TOMADAS EM CASO DE ACIDENTE:
A24: Todo e qualquer acidente de trabalho, deverá ser comunicado para o encarregado, na falta deste para o membro da CIPA e/ou ao Departamento Pessoal, para que possa ser providenciada a emissão da CAT – Comunicação de Acidente do Trabalho, cujo prazo é de 24 horas.
A25: OBS: O ACIDENTE NÃO COMUNICADO, NÃO SERÁ CONSIDERADO PARA EFEITOS LEGAIS.
A26: PROIBIÇÕES
A27: O descumprimento do aqui estabelecido importará em ato faltoso do integrante, com aplicação de penalidades cabíveis, baseadas no artigo 158 da C.L.T. e bem com o estabelecido nas cláusulas contratuais.
... A33: ATIVIDADES HABITUAIS
A34: =VLOOKUP(D8,'MATRIZ FUNÇÃO'!A:F,5,0) -> DESCRIÇÃO SINTÉTICA: Atuar em atividades auxiliares relativas à execução de obras em geral DESCRIÇÃO DETALHADA: Executar trabalhos auxiliares, sob supervisão, de serviços de alvenaria, concreto e outros materiais, auxiliando em processos pertinentes para construir, reformar ou reparar prédios e obras similares; Preparar concretos e argamassas segundo as características da obra e orientação superior. Assentar diferentes materiais, sob orientação; Revestir diferentes superfícies, sob supervisão; Realizar reforma e manutenção de prédios, calçadas e outras estruturas, sob Supervisão superior; Auxiliar na instalação de molduras de portas, janelas, quadro de luz e outros; Auxiliar na armação e desmonte andaimes de madeira ou metálicos para execução de obras desejadas; Auxiliar na montagem tubulações para instalações elétricas; Realizar treinamento na área de atuação, quando solicitado; Atuar, na qualidade de instrutor de treinamentos e outros eventos de igual natureza, mediante participação prévia em processo de qualificação e autorização superior; Manter organizados, limpos e conservados os materiais, máquinas, equipamentos e local de trabalho; Auxiliar na limpeza de frente de trabalho; Auxiliar na recomposição de materiais com carrinho de mão; Executar serviços manuais, utilizando ferramentas como: pá, enxada, picareta, vassoura, carrinho de mão entre outros; Montagem e desmontagem de barracas, utilizadas na área de vivencia Limpeza, retirada de lixo das áreas de vivencia; Orientar operadores e motoristas em manobras; Executar carregamento de peso manual; Auxiliar na medição camadas fresadas, utilizando linhas, trenas e outros; Pulverizar com óleo vegetal os pneus dos rolos durante a operação; Auxiliar no assopramento da areia de aplicação do material; Escavar valas, fixar piquetes; Executar tarefas manuais rotineiras que exigem esforços físicos; Remover e Manusear volumes, maquinas, moveis e equipamentos sempre que solicitado; Auxiliar na faxina em geral;
A36: TERMO DE RECEBIMENTO E COMPROMISSO
A37: Recebi da Empresa Talude Construções SA, a Ordem de Serviço (OS) que agora assino referente às minhas funções, que foi elaborada atendendo a legislação trabalhista em vigor, na qual cumprirei.
A38: DADOS DO FUNCIONÁRIO E ASSINATURA
A39: NOME LEGIVEL: | B39: =B9 -> JOSE ANDRE DE SANTANA CRISPIM
A40: IDENTIDADE: | B40: =VLOOKUP(D7,'MATRIZ FUNCIONÁRIOS'!A:F,6,0) -> 3140099 | C40: CPF: | D40: =VLOOKUP(D7,'MATRIZ FUNCIONÁRIOS'!A:F,5,0) -> 068.473.064-24
A41: FUNÇÃO: | B41: =D9 -> AJUDANTE DE OBRAS | C41: DATA: | D41: =VLOOKUP(D7,'MATRIZ FUNCIONÁRIOS'!A:H,7,0) -> 0
A42: ASSINATURA: | B42: x
A46: GILTON PEREIRA MIRANDA
A47: TÉCNICO DE SEGURANÇA DO TRABALHO
A48: Registro MTE-SP 0123056
A49: INSTRUTOR

Sheet FICHA DE EPI
A1: AAHBRANT ENGENHARIA E CONSTRUÇÕES LTDA
A4: TERMO DE RESPONSABILIDADE E CONTROLE DE ENTREGA DE EQUIPAMENTO DE PROTEÇÃO INDIVIDUAL - EPI
A6: COLABORADOR: | C6: =VLOOKUP(G7,'MATRIZ FUNCIONÁRIOS'!A:F,2,0) -> JOSÉ IGOR GALVÃO SILVA
A7: FUNÇÃO: | C7: =VLOOKUP(G7,'MATRIZ FUNCIONÁRIOS'!A:F,3,0) -> AJUDANTE DE OBRAS | F7: MATRIC: | G7: 550
A8: DATA ADMISSÃO: | C8: =VLOOKUP(G7,'MATRIZ FUNCIONÁRIOS'!A:G,7,0) -> 46259 | F8: SETOR: | G8: =VLOOKUP(G7,'MATRIZ FUNCIONÁRIOS'!A:H,8,0) -> OPERACIONAL
A9: DECLARAÇÃO DE RECEBIMENTO DE EPI
A10: Declaro em conformidade ao artigo 166 da Lei 6514/77 e NR-6 portaria 3214/78 do MTe, ter recebido gratuitamente os “Equipamentos de Proteção Individual – EPI” abaixo descritos, os quais me obrigo a usá-los, sistematicamente, em minhas atividades na empresa. Declaro também, que recebi orientação adequada quanto ao uso, finalidade, higienização, guarda conservação e ocasiões de substituições dos equipamentos de segurança abaixo descritos. Declaro ainda, ter ciência de que: a. Os EPIs deverão ser utilizados unicamente para o fim a que se destinam; b. Qualquer alteração que os tornem danificados deverá ser por mim comunicados à minha empregadora; c. A falta do uso por mim dos EPIs, fornecidos pela minha empregadora, constitui ato faltoso sujeito as sanções disciplinares previstas na legislação, no Regulamento Interno e nas Normas de Segurança da Empresa, aplicáveis ao assunto, inclusive e, especialmente, a demissão por justa causa. d. Responsabilizar-me-ei, integralmente, pela guarda e conservação dos EPIs, que me forem entregues; e. A minha empregadora fica expressamente autorizada a descontar dos meus salários bem como de indenizações, os valores dos EPIs, que porventura eu danificar culposa ou dolosamente, extrair e/ou não devolver para substituição ou por ocasião de meu desligamento da empresa. Finalmente, declaro que estou de acordo com todos os termos presentes, razão pela qual assino nesta data.
A11: Informe o Código correspondente ao motivo da aquisição
A12: (A) 1ª aquisição / (B) Gasto Normal / (C) Danos / (D) extraviados/ (E) Acidente
A14: QUANT | B14: DESCRIÇÃO DO EQUIPAMENTO | D14: NºCA | E14: DATA ENTREGA | F14: CÓD | G14: ASSINATURA | H14: DATA DEVOL.
A15: 2 | B15: CONJUNTO UNIFORMES | D15: UNI | E15: 46251 | F15: B | G15: X
A16: 1 | B16: BOTINA DE SEGURANÇA | D16: 38362 | E16: 46251 | F16: =F15 -> B | G16: x
A17: 1 | B17: PROTETOR AURICULAR TIPO PLUG | D17: 10043 | E17: 46251 | F17: =F16 -> B | G17: x
A18: 2 | B18: RESPIRADOR PFF2VS | D18: 45364 | E18: 46251 | F18: B | G18: x
A19: 1 | B19: =VLOOKUP(D19,'[1]MATRIZ EPI'!A:B,2,0) -> PROTETOR SOLAR LUVEX UV F60 | D19: SOL | E19: 46251 | F19: =F18 -> B | G19: x
A20: 1 | B20: ='MATRIZ EPI'!B9 -> ÓCULOS DE SEGURANÇA | D20: 11268 | E20: 46251 | F20: =F19 -> B | G20: x
A21: 1 | B21: CAPACETE DE SEG. | D21: 31469 | E21: 46251 | F21: =F20 -> B | G21: x
A22: 1 | B22: PAR DE LUVAS PIGMENTA | D22: 37930 | E22: 46251 | F22: =F21 -> B | G22: X
A23: 1 | B23: OCULOS DE SEG. INCOLOR | D23: 11268 | E23: 46251 | F23: =F22 -> B | G23: x
A24: (A) 1ª aquisição / (B) Gasto Normal / (C) Danos / (D) extraviados/ (E) Acidente
A25: DADOS DO FUNCIONÁRIO E ASSINATURA
A26: NOME LEGÍVEL: | C26: =C6 -> JOSÉ IGOR GALVÃO SILVA
A27: IDENTIDADE: | C27: =VLOOKUP(G7,'MATRIZ FUNCIONÁRIOS'!A:H,6,0) -> 71147506418 | E27: CPF: | F27: =VLOOKUP(G7,'MATRIZ FUNCIONÁRIOS'!A:H,5,0) -> 711.475.064-18
A28: FUNÇÃO: | C28: =C7 -> AJUDANTE DE OBRAS | E28: DATA ADM: | F28: =C8 -> 46259
A29: ASSINATURA: | C29: X
A31: AAHBRANT ENGENHARIA E CONSTRUÇÕES LTDA
A34: TERMO DE RESPONSABILIDADE E CONTROLE DE ENTREGA DE EQUIPAMENTO DE PROTEÇÃO INDIVIDUAL - EPI
A36: COLABORADOR: | C36: =C6 -> JOSÉ IGOR GALVÃO SILVA
A37: FUNÇÃO: | C37: =C7 -> AJUDANTE DE OBRAS | F37: MATRIC: | G37: =G7 -> 550
A38: DATA ADMISSÃO: | C38: =C8 -> 46259 | F38: SETOR: | G38: =G8 -> OPERACIONAL
A39: QUANT | B39: DESCRIÇÃO DO EQUIPAMENTO | D39: NºCA | E39: DATA ENTREGA | F39: CÓD | G39: ASSINATURA | H39: DATA DEVOL.
G40: X
G41: X
G42: X
G43: X
G44: X
G45: X
G46: X
G47: X
G48: X
...

Sheet MATRIZ FUNÇÃO
A1: CBO | B1: FUNÇÃO | C1: DESCRIÇÃO SUMÁRIA | D1: RISCOS | E1: ATIVIDADES | F1: CARGOS | G1: SETOR
A2: 717020 | B2: AJUDANTE DE OBRAS | C2: Ajudam a executar tarefa de demolição de estrutura de alvenaria, Quebra de pisos e bases de concreto, construção e reparos em edificações de alvenaria, executar escavações, escoramento de valas e recomposição de pisos, Ajuda a executar paredes de alvenaria, executar trabalhos de retiradas de entulhos, espalhamento de materiais, carregamento e descarregamentos, desvios de trânsito auxilia na sinalização. | D2: FISICO: RUIDO, RADIAÇÃO NÃO IONIZANTES. QUÍMICO: POEIRAS MINERAIS (SILICA LIVRE CRISTALIZADA) ERGONOMICO: POSTURA INADEQUADA. ACIDENTE:ATROPELAMENTOS, BATIDAS CONTRA, CORTES E PERFURAÇÕES, PROJEÇÃO DE PARTICULAS, QUEDA DE MESMO NÍVEL. | E2: DESCRIÇÃO SINTÉTICA: Atuar em atividades auxiliares relativas à execução de obras em geral DESCRIÇÃO DETALHADA: Executar trabalhos auxiliares, sob supervisão, de serviços de alvenaria, concreto e outros materiais, auxiliando em processos pertinentes para construir, reformar ou reparar prédios e obras similares; Preparar concretos e argamassas segundo as características da obra e orientação superior. Assentar diferentes materiais, sob orientação; Revestir diferentes superfícies, sob supervisão; Realizar reforma e manutenção de prédios, calçadas e outras estruturas, sob Supervisão superior; Auxiliar na instalação de molduras de portas, janelas, quadro de luz e outros; Auxiliar na armação e desmonte andaimes de madeira ou metálicos para execução de obras desejadas; Auxiliar na montagem tubulações para instalações elétricas; Realizar treinamento na área de atuação, quando solicitado; Atuar, na qualidade de instrutor de treinamentos e outros eventos de igual natureza, mediante participação prévia em processo de qualificação e autorização superior; Manter organizados, limpos e conservados os materiais, máquinas, equipamentos e local de trabalho; Auxiliar na limpeza de frente de trabalho; Auxiliar na recomposição de materiais com carrinho de mão; Executar serviços manuais, utilizando ferramentas como: pá, enxada, picareta, vassoura, carrinho de mão entre outros; Montagem e desmontagem de barracas, utilizadas na área de vivencia Limpeza, retirada de lixo das áreas de vivencia; Orientar operadores e motoristas em manobras; Executar carregamento de peso manual; Auxiliar na medição camadas fresadas, utilizando linhas, trenas e outros; Pulverizar com óleo vegetal os pneus dos rolos durante a operação; Auxiliar no assopramento da areia de aplicação do material; Escavar valas, fixar piquetes; Executar tarefas manuais rotineiras que exigem esforços físicos; Remover e Manusear volumes, maquinas, moveis e equipamentos sempre que solicitado; Auxiliar na faxina em geral; | F2: CARGO: AJUDANTE DE OBRAS FUNÇÃO: SERVIÇOS OPERACIONAIS NA EXECUÇÃO DE OBRAS CBO: 7170-20 | G2: PRODUÇÃO
A3: 717020-A | B3: AJUDANTE DE OBRAS (TRABALHO EM ALTURA) | C3: Ajudam a executar tarefa de demolição de estrutura de alvenaria, Quebra de pisos e bases de concreto, construção e reparos em edificações de alvenaria, executar escavações, escoramento de valas e recomposição de pisos, Ajuda a executar paredes de alvenaria, executar trabalhos de retiradas de entulhos, espalhamento de materiais, carregamento e descarregamentos, desvios de trânsito auxilia na sinalização. | D3: FISICO: RUIDO, RADIAÇÃO NÃO IONIZANTES. QUÍMICO: POEIRASMINERAIS (SILICA LIVRE CRISTALIZADA) ERGONOMICO: POSTURA INADEQUADA. ACIDENTE:ATROPELAMENTOS, BATIDAS CONTRA, PROJEÇÃO DE PARTICULAS, QUEDA DE MESMO NÍVEL E TRABALHO EM ALTURA. | E3: DESCRIÇÃO SINTÉTICA: Atuar em atividades auxiliares relativas à execução de obras em geral DESCRIÇÃO DETALHADA: Executar trabalhos auxiliares, sob supervisão, de serviços de alvenaria, concreto e outros materiais, auxiliando em processos pertinentes para construir, reformar ou reparar prédios e obras similares; Preparar concretos e argamassas segundo as características da obra e orientação superior. Assentar diferentes materiais, sob orientação; Revestir diferentes superfícies, sob supervisão; Realizar reforma e manutenção de prédios, calçadas e outras estruturas, sob Supervisão superior; Auxiliar na instalação de molduras de portas, janelas, quadro de luz e outros; Auxiliar na armação e desmonte andaimes de madeira ou metálicos para execução de obras desejadas; Auxiliar na montagem tubulações para instalações elétricas; Realizar treinamento na área de atuação, quando solicitado; Atuar, na qualidade de instrutor de treinamentos e outros eventos de igual natureza, mediante participação prévia em processo de qualificação e autorização superior; Manter organizados, limpos e conservados os materiais, máquinas, equipamentos e local de trabalho; Auxiliar na limpeza de frente de trabalho; Auxiliar na recomposição de materiais com carrinho de mão; Executar serviços manuais, utilizando ferramentas como: pá, enxada, picareta, vassoura, carrinho de mão entre outros; Montagem e desmontagem de barracas, utilizadas na área de vivencia Limpeza, retirada de lixo das áreas de vivencia; Orientar operadores e motoristas em manobras; Executar carregamento de peso manual; Auxiliar na medição camadas fresadas, utilizando linhas, trenas e outros; Pulverizar com óleo vegetal os pneus dos rolos durante a operação; Auxiliar no assopramento da areia de aplicação do material; Escavar valas, fixar piquetes; Executar tarefas manuais rotineiras que exigem esforços físicos; Remover e Manusear volumes, maquinas, moveis e equipamentos sempre que solicitado; Auxiliar na faxina em geral; | F3: CARGO: AJUDANTE DE OBRAS FUNÇÃO: SERVIÇOS OPERACIONAIS NA EXECUÇÃO DE OBRAS CBO: 7170-20 | G3: PRODUÇÃO
A4: 715315 | B4: ARMADOR | C4: Preparar formas de madeira, colocando ferragens no interior das mesmas, baseando-se nas especificações ouinstruções recebidas, cortando, curvando e unindo vergalhões com a ajuda de ferramentas manuais, máquinas e outros utensílios, sob orientação do seu superior. | D4: FISICO: RUIDO, RADIAÇÃO NÃO IONIZANTE. QUÍMICO: POEIRAS MINERAIS (SILICA LIVRE CRISTALIZADA) , POEIRAS METÁLICAS. ERGONOMICO: POSTURA INADEQUADA. ACIDENTE: ATROPELAMENTO, BATIDAS CONTRA, CORTES E PERFURAÇÕES, PROJEÇÃO DE PARTÍCULAS E QUEDA DE MESMO NÍVEL. | E4:  DESCRIÇÃO SINTÉTICA:  Atuar em atividades relativas à área de confecção de armações e estruturas de concreto e madeira.Preparar a confecção de armações de estruturas de concreto e de corpos de provas;  Montar armações de ferragens em geral;  Cortar e dobrar ferragens;  Aplicação de armações e formações de lajes e vigas;  Realizar treinamento na área de atuação, quando solicitado;  Execultar cortes e dobras de ferragens;  Amarra as ferragens utilizando turquesas e arrames;  Montar ferragens de acordo com o projeto orientado pelo encarregado;  Efetuar carregamento manual de ferragens;  Manter organizados, limpos e conservados os materiais, máquinas, equipamentos e local de trabalho, que estão sob sua responsabilidade;  Ler,Interpretar e seguir projetos;  Zelar e manter sob sua reponsabilidade os ferramentais de uso. | F4: CARGO: ARMADOR;:FUNÇÃO: SERVIÇOS DE CONFECÇÃO DE ARMAÇÕES FERRAGEM - CBO: 7153-15 | G4: PRODUÇÃO
A5: 715315 (A) | B5: ARMADOR | C5: Preparar formas de madeira, colocando ferragens no interior das mesmas, baseando-se nas especificações ouinstruções recebidas, cortando, curvando e unindo vergalhões com a ajuda de ferramentas manuais, máquinas e outros utensílios, sob orientação do seu superior. | D5: FISICO: RUIDO, RADIAÇÃO NÃO IONIZANTE. QUÍMICO: POEIRAS POEIRAS MINERAIS (SILICA LIVRE CRISTALIZADA), POEIRAS METÁLICAS. ERGONOMICO: POSTURA INADEQUADA. ACIDENTE: ATROPELAMENTO, BATIDAS CONTRA, CORTES E PERFURAÇÕES, PROJEÇÃO DE PARTÍCULAS, QUEDA DE MESMO NÍVEL E TRABALHO EM ALTURA. | E5:  DESCRIÇÃO SINTÉTICA:  Atuar em atividades relativas à área de confecção de armações e estruturas de concreto e madeira.Preparar a confecção de armações de estruturas de concreto e de corpos de provas;  Montar armações de ferragens em geral;  Cortar e dobrar ferragens;  Aplicação de armações e formações de lajes e vigas;  Realizar treinamento na área de atuação, quando solicitado;  Execultar cortes e dobras de ferragens;  Amarra as ferragens utilizando turquesas e arrames;  Montar ferragens de acordo com o projeto orientado pelo encarregado;  Efetuar carregamento manual de ferragens;  Manter organizados, limpos e conservados os materiais, máquinas, equipamentos e local de trabalho, que estão sob sua responsabilidade;  Ler,Interpretar e seguir projetos;  Zelar e manter sob sua reponsabilidade os ferramentais de uso. | F5: CARGO: ARMADOR;:FUNÇÃO: SERVIÇOS DE CONFECÇÃO DE ARMAÇÕES FERRAGEM - CBO: 7153-15 | G5: PRODUÇÃO
A6: 312105-M | B6: ASSIST. TEC. DE MEDIÇÃO | C6: Realiza medições de obras, de acordo com dados levantados na topografia, para determinar quantidades e custos de materiais, mão de obra, equipamento e serviços necessários. | D6: FISICO: RUIDO, RADIAÇÃO NÃO IONIZANTE. QUÍMICO: POEIRAS MINERAIS (SILICA LIVRE CRISTALIZADA), ERGONOMICO: POSTURA INADEQUADA ACIDENTE: ACIDENTES DE TRANSITO (COLISÕES E ATROPELAMENTOS) BATIDAS CONTRA, QUEDA DE MESMO NÍVEL.. | E6: DESCRIÇÃO SINTÉTICA:  Auxiliar na elaborar, executar e dirigir projetos de engenharia civil. DESCRIÇÃO DETALHADA:  Auxilia na elaborar projetos de engenharia relativos a estrutura de edificações, tráfegos, vias urbanas e obras de pavimentação, sistemas de água e esgoto, aproveitamento de  Recursos naturais, serviços de equipamentos urbanos, rurais e regionais, entre outros;  Estudar características, especificações e preparar plantas, orçamentos de custos,técnicas de execução e outros dados, para possibilitar e orientar a construção,manutenção e reparo das obras, dentro dos padrões técnicos exigidos;  Efetuar vistorias, perícias, avaliação de imóveis, arbitramento, emitindo laudos e pareceres técnicos;  Participar de planos gerais e específicos, que visem o posicionamento institucional frente à comunidade, no que tange a sua especialidade e formação;  Realizar treinamento na área de atuação, quando solicitado;  Atuar, na qualidade de instrutor de treinamentos e outros eventos de igual natureza,mediante participação prévia em processo de qualificação e autorização superior;  Operar equipamentos e sistemas de informática e outros, quando autorizado e  Necessário ao exercício das demais atividades;  Dirigir veículos leves, mediante autorização prévia, quando necessário ao exercício das demais atividades; | F6: CARGO: ASSISTENTE DE ENGENHARIA FUNÇÃO: ASSISTENTE DE ENGENHARIA CBO:312105 | G6: ADMINISTRATIVO
A7: 715505 | B7: CARPINTEIRO | C7: Auxilia na construção, montagem e transporte, das formas e caixaria de madeira para a estrutura (vigas, colunas, sapatas, pilares) dos edifícios e obras similares, utilizando processos e ferramentas manuais e mecânicas, para compor tesouras, armações de telhado, andaimes e outros materiais afins, Executa trabalhos de carpintaria, com, desbaste e armação de portas, janelas, caixilhos e outros em esquadrias de madeira, Executa trabalhos em madeira, com base em desenhos, croquis ou ordens de serviços, montagens, reparos ou modificações em estrutura de alvenaria, portas, divisórias, engradados, etc, Efetua levantamento dos materiais necessários, selecionando e preparando os mesmos de acordo com os trabalhos a serem realizados. Operam máquinas, ferramentas e/ou instrumentos, a fim de lixar, cortar, plainar, montar. | D7: FISICO: RUIDO, RADIAÇÕES NÃO IONIZANTES; QUÍMICO: POEIRAS DE MADEIRA, DESMOLDANTE MINERAIS (SILICA LIVRE CRISTALIZADA); ERGONOMICO: POSTURA INADEQUADA. ACIDENTE: ATROPELAMENTO, BATIDA CONTRA, CORTE E PERFURAÇÕES, PROJEÇÕES DE PARTÍCULAS E QUEDA DE MESMO NÍVEL, | E7: DESCRIÇÃO SINTÉTICA:  Atuar em atividades relativas à área de carpintaria. DESCRIÇÃO DETALHADA:  Montagem e desmontagem de formas /Ecoramentos/Cimbramentos;  Auxiliar reajuste de formas no momento da concretagem;  Auxiliar em atividades relacionadas a reformas e construções, segundo orientação;  Montar andaimes, caixarias e tapumes de madeira;  Executar serviços diversos de carpintaria em geral, segundo orientações;  Realizar treinamento na área de atuação, quando solicitado;  Reparar elementos de madeira, substituindo total ou parcialmente peças desgastadas ou deterioradas ou fixando partes soltas para recompor sua estrutura;  Afiar ferramentas de corte, utilizando rebolo, lima, assentador ou pedra de afiar, para manter o gume;  Manter organizados, limpos e conservados os materiais, máquinas, equipamentos e local de trabalho, que estão sob sua responsabilidade;  Montar e desmontar andaimes;  Nivelar e alinhar formas,escorametos e cimbramentos;  Ler,Interpretar e seguir projetos;  Zelar e manter sob sua reponsabilidade os ferramentais de uso | F7: CARGO: CARPINTEIRO FUNÇÃO: SERVIÇOS DE CARPINTARIA CBO: 7155-05 | G7: PRODUÇÃO
A8: 715615 | B8: AUXILIAR DE ELETRICISTA | C8: Realiza instalações provisórias nas frentes de serviço, Realiza revisões dos cabos e ligações elétricas em máquinas e equipamentos, Executa verificação de painéis elétricos nos canteiros, Executa pequenas manutenções em ferramentas elétricas, Revisa os sistemas de iluminação e distribuição de energia nos canteiros, Realiza serviços de aterramento em diversos serviços, Testa e identifica redes e quadros. | D8: FISICO: RUIDO, RADIAÇÃO NÃO IONIZANTE. QUÍMICO: POEIRAS MINERAIS (SILICA LIVRE CRISTALIZADA) ERGONOMICO: POSTURA INADEQUADA ACIDENTE: ATROPELAMENTOS, CHOQUE ELÉTRICO, QUEDA DE MESMO NÍVEL.. | E8: PLANEJAR SERVIÇOS ELÉTRICOS REALIZAR INSTALAÇÃO DE DISTRIBUIÇÃO DE ALTA E BAIXA TENSÃO REALIZAR INSTALAÇÕES ELÉTRICAS PREDIAIS FAZER INSTALAÇÃO INDUSTRIAL EFETUAR SERVIÇOS COMERCIAIS DE ALTA E BAIXA TENSÃO Planejam serviços elétricos, realizam instalação de distribuição de alta e baixa tensão. Montam e reparam instalações elétricas e equipamentos auxiliares em residências, estabelecimentos industriais, comerciais e de serviços. Instalam e reparam equipamentos de iluminação de cenários ou palcos. EXECUTAR SERVIÇOS DE MANUTENÇÃO PREVENTIVA | F8: CARGO: ELETRICISTA FUNÇÃO: ELETRICISTA CBO: 7156-05 | G8: PRODUÇÃO
A9: 715605 | B9: ELETRICISTA | C9: Realiza instalações provisórias nas frentes de serviço, Realiza revisões dos cabos e ligações elétricas emmáquinas e equipamentos, Executa verificação de painéis elétricos nos canteiros, Executa pequenas manutenções em ferramentas elétricas, Revisa os sistemas de iluminação e distribuição de energia nos canteiros, Realiza serviços de aterramento em diversos serviços, Testa e identifica redes e quadros. | D9: FISICO: RUIDO, RADIAÇÃO NÃO IONIZANTE. QUÍMICO: POEIRAS MINERAIS (SILICA LIVRE CRISTALIZADA). ERGONOMICO: POSTURA INADEQUADA ACIDENTE: ATROPELAMENTOS, CHOQUE ELÉTRICO, QUEDA DE MESMO NÍVEL.. | E9: PLANEJAR SERVIÇOS ELÉTRICOS REALIZAR INSTALAÇÃO DE DISTRIBUIÇÃO DE ALTA E BAIXA TENSÃO REALIZAR INSTALAÇÕES ELÉTRICAS PREDIAIS FAZER INSTALAÇÃO INDUSTRIAL EFETUAR SERVIÇOS COMERCIAIS DE ALTA E BAIXA TENSÃO Planejam serviços elétricos, realizam instalação de distribuição de alta e baixa tensão. Montam e reparam instalações elétricas e equipamentos auxiliares em residências, estabelecimentos industriais, comerciais e de serviços. Instalam e reparam equipamentos de iluminação de cenários ou palcos. EXECUTAR SERVIÇOS DE MANUTENÇÃO PREVENTIVA | F9: CARGO: ELETRICISTA FUNÇÃO: ELETRICISTA CBO: 7156-05 | G9: PRODUÇÃO
A10: 514320 | B10: FAXINEIRO | C10: Realiza faxina nos escritórios e canteiro da obra, recolhe os lixos armazena em locais adequado. | D10: FISICO: RUIDO. QUÍMICO: POEIRAS MINERAIS (SILICA LIVRE CRISTALIZADA) ; PRODUTOS QUIMICOS DE USO DOMESTICO. BIOLÓGICO: FUNGOS, VIRUS E BACTÉRIAS (LIMPEZA); ERGONOMICO: POSTURA EM PÉ POR LONGOS PERIODOS ACIDENTE: QUEDA DE MESMO NÍVEL. | E10: LIMPAR RECINTOS E ACESSÓRIOS Limpar vidros Remover resíduos dos vidros Limpar móveis e equipamentos Limpeza de sanitários Limpar superfícies (paredes, pisos, etc..) Aspirar pó Lavar pisos Encerar pisos Remover sujeira Varrer pisos Secar pisos Passar pano Limpar cortinas e persianas Recolher lixo | F10: CARGO: FAXINEIRA FUNÇÃO: FAXINEIRA CBO: 5143-20 | G10: LIMPEZA
A11: 312320-G | B11: GREIDISTA | C11: Realiza cálculo de material a ser usado em terraplanagem, orienta e acompanha trabalho de corte e aterro, nivelamento e compactação de pistas e verifica estacas e marcações. | D11: FISICO: RUIDO, RADIAÇÃO NÃO IONIZANTE. QUÍMICO: POEIRAS MINERAIS (SILICA LIVRE CRISTALIZADAS) ERGONOMICO: POSTURA INADEQUADA ACIDENTE:ATROPELAMENTOS, BATIDAS CONTRA, QUEDA DE MESMO NÍVEL. | E11: Executam levantamentos geodésicos e topohidrográficos, por meio de levantamentos altimétricos e planimétricos; implantam, no campo, pontos de projeto, locando obras de sistemas de transporte, obras civis, industriais, rurais e delimitando glebas; planejam trabalhos em geomática; analisam documentos e informações cartográficas, interpretando fotos terrestres, fotos aéreas, imagens orbitais, cartas, mapas, plantas, identificando acidentes geométricos e pontos de apoio para georeferenciamento e amarração, coletando dados geométricos. Efetuam cálculos e desenhos e elaboram documentos cartográficos, definindo escalas e cálculos cartográficos, efetuando aerotriangulação, restituindo fotografias aéreas. | F11: CARGO: GREIDISTA FUNÇÃO: GREIDISTA CBO: 3123-20 | G11: PRODUÇÃO
A12: 7825.10-C | B12: MOTORISTA DE CAMINHAO | C12: Transportam, coletam e entregam cargas em geral, guincham, destombam e removem veículos avariados e prestam socorro mecânico. Movimentam cargas volumosas e pesadas, podem, também, operar equipamentos, realizar inspeções e reparos em veículos, vistoriar cargas, além de verificar documentação de veículos e de cargas. Definem rotas e asseguram a regularidade do transporte. As atividades são desenvolvidas em conformidade com normas e procedimentos técnicos e de segurança. | D12: RISCO FISICO: RUIDO, RADIAÇÃO NÃO IONIZANTE, VIBRAÇÕES DE CORPO INTEIRO. RISCO QUÍMICO: POEIRAS MINERAIS (SILICA LIVRE CRISTALIZADA) ; RISCO ERGONÔMICO: POSTURA INADEQUADA RISCO DE ACIDENTE: COLISÃO E TOMBAMENTO, BATIDAS CONTRA, QUEDA DO MESMO NÍVEL | E12: DESCRIÇÃO SINTÉTICA:  Condução de veículos de médio e grande porte. DESCRIÇÃO DETALHADA:  Dirigir veículos de médio e grande porte;  Transportar materiais, equipamentos e documentos;  Verificar, diariamente, as condições de funcionamento do veículo, antes de sua Utilização;  Comunicar a chefia imediata por escrito assinando a comunicação da necessidade de reparos no veículo;  Zelar pela segurança de passageiros no caso de ajudante;  Orientar e auxiliar na carga e descarga de materiais;  Amarrar a carga e conferir;  Atentar – se ao peso da carga e zelar pelo equipamento;  Registrar dados preestabelecidos, sobre a utilização diária do veículo;  Verificar, trocar ou completar, se necessário cotidianamente o óleo, a água e o Combustível;  Efetuar limpeza dos materiais que ficam encostados na caçamba;  Limpar placas, faróis e sinaleiros dos veículos utilizados;  Estar sempre atualizado com as leis e normas de trânsito e respeita- las;  Realizar treinamento na área de atuação, quando solicitado;  Utilizar a carga horária que lhe é pertinente com zelo, dedicação, responsabilidade e a serviço da Empresa;  Manter organizados, limpos e conservados os materiais, máquinas, equipamentos e local de trabalho, que estão sob sua responsabilidade;  Operar de acordo com a capacidade e especificações do fabricante. | F12: CARGO: SERVIÇO DE CONDUÇÃO DE VEÍCULOS DE MÉDIO E GRANDE PORTE. FUNÇÃO: MOTORISTA CBO: 7823-05 | G12: PRODUÇÃO
